<?xml version="1.0" encoding="utf-8"?>
<!-- This URDF was automatically created by SolidWorks to URDF Exporter! Originally created by Stephen Brawner (brawner@gmail.com) 
     Commit Version: 1.6.0-4-g7f85cfe  Build Version: 1.6.7995.38578
     For more information, please see http://wiki.ros.org/sw_urdf_exporter -->
<robot
  name="carver_description">

  <link name="world"></link>
  <joint name="world_base_joint" type="fixed">
    <parent link="world" /> 
    <child link="base_link" />
    <origin xyz="0 0 0.345" rpy="0 0 0" />
  </joint>

  <link
    name="base_link">
    <inertial>
      <origin
        xyz="-0.072041 -0.00014094 0.20657"
        rpy="0 0 0" />
      <mass
        value="300" />
      <inertia
        ixx="14.92"
        ixy="3.4379E-05"
        ixz="0.03342"
        iyy="50.002"
        iyz="-0.0013248"
        izz="56.266" />
    </inertial>
    <visual>
      <origin
        xyz="0 0 0"
        rpy="0 0 0" />
      <geometry>
        <mesh
          filename="package://carver_description/meshes/base_link.STL" />
      </geometry>
      <material
        name="">
        <color
          rgba="0.79216 0.81961 0.93333 1" />
      </material>
    </visual>
    <collision>
      <origin
        xyz="0 0 0"
        rpy="0 0 0" />
      <geometry>
        <mesh
          filename="package://carver_description/meshes/base_link.STL" />
      </geometry>
    </collision>
  </link>
  <link
    name="SRF_Link">
    <inertial>
      <origin
        xyz="-6.8701E-09 3.5107E-09 -0.01125"
        rpy="0 0 0" />
      <mass
        value="0.030742" />
      <inertia
        ixx="5.1583E-06"
        ixy="2.8769E-08"
        ixz="-2.3779E-12"
        iyy="5.9471E-06"
        iyz="1.7959E-13"
        izz="8.1771E-06" />
    </inertial>
    <visual>
      <origin
        xyz="0 0 0"
        rpy="0 0 0" />
      <geometry>
        <mesh
          filename="package://carver_description/meshes/SRF_Link.STL" />
      </geometry>
      <material
        name="">
        <color
          rgba="0.79216 0.81961 0.93333 1" />
      </material>
    </visual>
    <collision>
      <origin
        xyz="0 0 0"
        rpy="0 0 0" />
      <geometry>
        <mesh
          filename="package://carver_description/meshes/SRF_Link.STL" />
      </geometry>
    </collision>
  </link>
  <joint
    name="base_SRF_joint"
    type="revolute">
    <origin
      xyz="0.63912 -0.2845 -0.15875"
      rpy="0 0 0" />
    <parent
      link="base_link" />
    <child
      link="SRF_Link" />
    <axis
      xyz="0 0 -1" />
    <limit
      lower="-3.14"
      upper="3.14"
      effort="100"
      velocity="100" />
  </joint>
  <link
    name="RF_Link">
    <inertial>
      <origin
        xyz="0.0013839 8.3267E-17 0.037975"
        rpy="0 0 0" />
      <mass
        value="5.0245" />
      <inertia
        ixx="0.045975"
        ixy="8.735E-19"
        ixz="0.0015276"
        iyy="0.045919"
        iyz="2.2305E-18"
        izz="0.087838" />
    </inertial>
    <visual>
      <origin
        xyz="0 0 0"
        rpy="0 0 0" />
      <geometry>
        <mesh
          filename="package://carver_description/meshes/RF_Link.STL" />
      </geometry>
      <material
        name="">
        <color
          rgba="0.79216 0.81961 0.93333 1" />
      </material>
    </visual>
    <collision>
      <origin
        xyz="0 0 0"
        rpy="0 0 0" />
      <geometry>
        <mesh
          filename="package://carver_description/meshes/RF_Link.STL" />
      </geometry>
    </collision>
  </link>
  <joint
    name="SRF_RF_joint"
    type="continuous">
    <origin
      xyz="-0.0040423 -0.11093 -0.01125"
      rpy="-1.5708 0 0" />
    <parent
      link="SRF_Link" />
    <child
      link="RF_Link" />
    <axis
      xyz="0.036418 0 0.99934" />
    <limit
      effort="100"
      velocity="100" />
  </joint>
  <link
    name="SLF_Link">
    <inertial>
      <origin
        xyz="7.1074E-09 -3.0013E-09 -0.01125"
        rpy="0 0 0" />
      <mass
        value="0.030742" />
      <inertia
        ixx="5.1583E-06"
        ixy="-2.88E-08"
        ixz="2.3846E-12"
        iyy="5.9471E-06"
        iyz="-6.0381E-15"
        izz="8.1771E-06" />
    </inertial>
    <visual>
      <origin
        xyz="0 0 0"
        rpy="0 0 0" />
      <geometry>
        <mesh
          filename="package://carver_description/meshes/SLF_Link.STL" />
      </geometry>
      <material
        name="">
        <color
          rgba="0.79216 0.81961 0.93333 1" />
      </material>
    </visual>
    <collision>
      <origin
        xyz="0 0 0"
        rpy="0 0 0" />
      <geometry>
        <mesh
          filename="package://carver_description/meshes/SLF_Link.STL" />
      </geometry>
    </collision>
  </link>
  <joint
    name="base_SLF_joint"
    type="revolute">
    <origin
      xyz="0.63912 0.2845 -0.15875"
      rpy="0 0 0" />
    <parent
      link="base_link" />
    <child
      link="SLF_Link" />
    <axis
      xyz="0 0 -1" />
    <limit
      lower="-3.14"
      upper="3.14"
      effort="100"
      velocity="100" />
  </joint>
  <link
    name="LF_Link">
    <inertial>
      <origin
        xyz="0.0013839 1.1102E-16 -0.037975"
        rpy="0 0 0" />
      <mass
        value="5.0245" />
      <inertia
        ixx="0.045975"
        ixy="5.6248E-19"
        ixz="-0.0015276"
        iyy="0.045919"
        iyz="-2.4402E-18"
        izz="0.087838" />
    </inertial>
    <visual>
      <origin
        xyz="0 0 0"
        rpy="0 0 0" />
      <geometry>
        <mesh
          filename="package://carver_description/meshes/LF_Link.STL" />
      </geometry>
      <material
        name="">
        <color
          rgba="0.79216 0.81961 0.93333 1" />
      </material>
    </visual>
    <collision>
      <origin
        xyz="0 0 0"
        rpy="0 0 0" />
      <geometry>
        <mesh
          filename="package://carver_description/meshes/LF_Link.STL" />
      </geometry>
    </collision>
  </link>
  <joint
    name="SLF_LF_joint"
    type="continuous">
    <origin
      xyz="-0.0040423 0.11093 -0.01125"
      rpy="-1.5708 0 0" />
    <parent
      link="SLF_Link" />
    <child
      link="LF_Link" />
    <axis
      xyz="0.036418 0 -0.99934" />
    <limit
      effort="100"
      velocity="100" />
  </joint>
  <link
    name="RB_Link">
    <inertial>
      <origin
        xyz="-2.2204E-16 -5.5511E-17 0.038"
        rpy="0 0 0" />
      <mass
        value="5.0245" />
      <inertia
        ixx="0.045919"
        ixy="-1.5683E-17"
        ixz="1.521E-19"
        iyy="0.045919"
        iyz="2.6608E-19"
        izz="0.087894" />
    </inertial>
    <visual>
      <origin
        xyz="0 0 0"
        rpy="0 0 0" />
      <geometry>
        <mesh
          filename="package://carver_description/meshes/RB_Link.STL" />
      </geometry>
      <material
        name="">
        <color
          rgba="0.79216 0.81961 0.93333 1" />
      </material>
    </visual>
    <collision>
      <origin
        xyz="0 0 0"
        rpy="0 0 0" />
      <geometry>
        <mesh
          filename="package://carver_description/meshes/RB_Link.STL" />
      </geometry>
    </collision>
  </link>
  <joint
    name="base_RB_joint"
    type="continuous">
    <origin
      xyz="-0.63688 -0.3955 -0.17"
      rpy="-1.5708 0 0" />
    <parent
      link="base_link" />
    <child
      link="RB_Link" />
    <axis
      xyz="0 0 1" />
    <limit
      effort="100"
      velocity="100" />
  </joint>
  <link
    name="LB_Link">
    <inertial>
      <origin
        xyz="-1.1102E-16 -5.5511E-17 -0.038"
        rpy="0 0 0" />
      <mass
        value="5.0245" />
      <inertia
        ixx="0.045919"
        ixy="-1.7045E-17"
        ixz="-1.6341E-20"
        iyy="0.045919"
        iyz="-3.0357E-19"
        izz="0.087894" />
    </inertial>
    <visual>
      <origin
        xyz="0 0 0"
        rpy="0 0 0" />
      <geometry>
        <mesh
          filename="package://carver_description/meshes/LB_Link.STL" />
      </geometry>
      <material
        name="">
        <color
          rgba="0.79216 0.81961 0.93333 1" />
      </material>
    </visual>
    <collision>
      <origin
        xyz="0 0 0"
        rpy="0 0 0" />
      <geometry>
        <mesh
          filename="package://carver_description/meshes/LB_Link.STL" />
      </geometry>
    </collision>
  </link>
  <joint
    name="base_LB_joint"
    type="continuous">
    <origin
      xyz="-0.63688 0.3955 -0.17"
      rpy="-1.5708 0 0" />
    <parent
      link="base_link" />
    <child
      link="LB_Link" />
    <axis
      xyz="0 0 -1" />
    <limit
      effort="100"
      velocity="100" />
  </joint>
</robot>