<?xml version="1.0" encoding="utf-8"?>
<!-- This URDF was automatically created by SolidWorks to URDF Exporter! Originally created by Stephen Brawner (brawner@gmail.com) 
     Commit Version: 1.6.0-4-g7f85cfe  Build Version: 1.6.7995.38578
     For more information, please see http://wiki.ros.org/sw_urdf_exporter -->
<robot
  name="carver_description">

  <link name="world"></link>

  <link
    name="base_link">
    <inertial>
      <origin
        xyz="-0.0716830244437461 -0.000140907088722169 0.206012930018474"
        rpy="0 0 0" />
      <mass
        value="363.855564635503" />
      <inertia
        ixx="14.9153288069886"
        ixy="-0.000117778849439372"
        ixz="0.0335924948549554"
        iyy="50.0022377740091"
        iyz="-0.00132352233715235"
        izz="56.2613234307726" />
    </inertial>
    <visual>
      <origin
        xyz="0 0 0"
        rpy="0 0 0" />
      <geometry>
        <mesh
          filename="package://carver_description/meshes/base_link.STL" />
      </geometry>
      <material
        name="">
        <color
          rgba="0.792156862745098 0.819607843137255 0.933333333333333 1" />
      </material>
    </visual>
    <collision>
      <origin
        xyz="0 0 0"
        rpy="0 0 0" />
      <geometry>
        <mesh
          filename="package://carver_description/meshes/base_link.STL" />
      </geometry>
    </collision>
  </link>

  <joint name="world_base_joint" type="fixed">
    <parent link="world" /> 
    <child link="base_link" />
    <origin xyz="0 0 0.345" rpy="0 0 0" />
  </joint>

  <link
    name="front_right_sterring_Link">
    <inertial>
      <origin
        xyz="-6.87012402522669E-09 3.51066137271872E-09 -0.0112499999237069"
        rpy="0 0 0" />
      <mass
        value="0.0307417074716638" />
      <inertia
        ixx="5.15827058483555E-06"
        ixy="2.87694711205719E-08"
        ixz="-2.37787643332467E-12"
        iyy="5.94711293506547E-06"
        iyz="1.79592218413634E-13"
        izz="8.17709432093611E-06" />
    </inertial>
    <visual>
      <origin
        xyz="0 0 0"
        rpy="0 0 0" />
      <geometry>
        <mesh
          filename="package://carver_description/meshes/front_right_sterring_Link.STL" />
      </geometry>
      <material
        name="">
        <color
          rgba="0.792156862745098 0.819607843137255 0.933333333333333 1" />
      </material>
    </visual>
    <collision>
      <origin
        xyz="0 0 0"
        rpy="0 0 0" />
      <geometry>
        <mesh
          filename="package://carver_description/meshes/front_right_sterring_Link.STL" />
      </geometry>
    </collision>
  </link>
  <joint
    name="base_front_right_sterring_joint"
    type="revolute">
    <origin
      xyz="0.639118924633511 -0.284499999999994 -0.158749999999999"
      rpy="0 0 0" />
    <parent
      link="base_link" />
    <child
      link="front_right_sterring_Link" />
    <axis
      xyz="0 0 -1" />
    <limit
      lower="-3.14"
      upper="3.14"
      effort="100"
      velocity="100" />
  </joint>
  <link
    name="front_right_wheel_Link">
    <inertial>
      <origin
        xyz="0.00138386531093282 8.32667268468867E-17 0.0379747931765428"
        rpy="0 0 0" />
      <mass
        value="5.024500013847" />
      <inertia
        ixx="0.0459745995956163"
        ixy="7.57697441098519E-19"
        ixz="0.00152760354434749"
        iyy="0.0459189311540779"
        iyz="2.23054422053752E-18"
        izz="0.0878380602731089" />
    </inertial>
    <visual>
      <origin
        xyz="0 0 0"
        rpy="0 0 0" />
      <geometry>
        <mesh
          filename="package://carver_description/meshes/front_right_wheel_Link.STL" />
      </geometry>
      <material
        name="">
        <color
          rgba="0.792156862745098 0.819607843137255 0.933333333333333 1" />
      </material>
    </visual>
    <collision>
      <origin
        xyz="0 0 0"
        rpy="0 0 0" />
      <geometry>
        <mesh
          filename="package://carver_description/meshes/front_right_wheel_Link.STL" />
      </geometry>
    </collision>
  </link>
  <joint
    name="front_right_steering_front_right_wheel_joint"
    type="continuous">
    <origin
      xyz="-0.00404234340824972 -0.110926369542007 -0.0112500000000002"
      rpy="-1.5707963267949 0 0" />
    <parent
      link="front_right_sterring_Link" />
    <child
      link="front_right_wheel_Link" />
    <axis
      xyz="0.036417508182449 0 0.999336662540598" />
    <limit
      effort="100"
      velocity="100" />
  </joint>
  <link
    name="front_left_sterring_Link">
    <inertial>
      <origin
        xyz="7.10743075504894E-09 -3.0012958229797E-09 -0.0112499999237069"
        rpy="0 0 0" />
      <mass
        value="0.0307417074716638" />
      <inertia
        ixx="5.15827283476504E-06"
        ixy="-2.88003004005144E-08"
        ixz="2.38464111325656E-12"
        iyy="5.94711068513598E-06"
        iyz="-6.03807310080527E-15"
        izz="8.17709432093612E-06" />
    </inertial>
    <visual>
      <origin
        xyz="0 0 0"
        rpy="0 0 0" />
      <geometry>
        <mesh
          filename="package://carver_description/meshes/front_left_sterring_Link.STL" />
      </geometry>
      <material
        name="">
        <color
          rgba="0.792156862745098 0.819607843137255 0.933333333333333 1" />
      </material>
    </visual>
    <collision>
      <origin
        xyz="0 0 0"
        rpy="0 0 0" />
      <geometry>
        <mesh
          filename="package://carver_description/meshes/front_left_sterring_Link.STL" />
      </geometry>
    </collision>
  </link>
  <joint
    name="base_front_left_sterring_joint"
    type="revolute">
    <origin
      xyz="0.639118924633511 0.284499999999994 -0.158749999999999"
      rpy="0 0 0" />
    <parent
      link="base_link" />
    <child
      link="front_left_sterring_Link" />
    <axis
      xyz="0 0 -1" />
    <limit
      lower="-3.14"
      upper="3.14"
      effort="100"
      velocity="100" />
  </joint>
  <link
    name="front_left_wheel_Link">
    <inertial>
      <origin
        xyz="0.00138386531093293 1.11022302462516E-16 -0.0379747931765427"
        rpy="0 0 0" />
      <mass
        value="5.02450001384701" />
      <inertia
        ixx="0.0459745995956163"
        ixy="5.29395592033849E-19"
        ixz="-0.00152760354434749"
        iyy="0.0459189311540779"
        iyz="-2.43852844580634E-18"
        izz="0.0878380602731089" />
    </inertial>
    <visual>
      <origin
        xyz="0 0 0"
        rpy="0 0 0" />
      <geometry>
        <mesh
          filename="package://carver_description/meshes/front_left_wheel_Link.STL" />
      </geometry>
      <material
        name="">
        <color
          rgba="0.792156862745098 0.819607843137255 0.933333333333333 1" />
      </material>
    </visual>
    <collision>
      <origin
        xyz="0 0 0"
        rpy="0 0 0" />
      <geometry>
        <mesh
          filename="package://carver_description/meshes/front_left_wheel_Link.STL" />
      </geometry>
    </collision>
  </link>
  <joint
    name="front_left_steering_front_left_wheel_joint"
    type="continuous">
    <origin
      xyz="-0.00404234340824972 0.110926369542007 -0.0112500000000002"
      rpy="-1.5707963267949 0 0" />
    <parent
      link="front_left_sterring_Link" />
    <child
      link="front_left_wheel_Link" />
    <axis
      xyz="0.036417508182449 0 -0.999336662540598" />
    <limit
      effort="100"
      velocity="100" />
  </joint>
  <link
    name="rear_right_wheel_Link">
    <inertial>
      <origin
        xyz="-1.11022302462516E-16 -8.32667268468867E-17 0.0379999999999999"
        rpy="0 0 0" />
      <mass
        value="5.024500013847" />
      <inertia
        ixx="0.0459189311540779"
        ixy="-1.55708478506981E-17"
        ixz="1.52096771869045E-19"
        iyy="0.045918931154078"
        iyz="2.66081321145035E-19"
        izz="0.0878937287146473" />
    </inertial>
    <visual>
      <origin
        xyz="0 0 0"
        rpy="0 0 0" />
      <geometry>
        <mesh
          filename="package://carver_description/meshes/rear_right_wheel_Link.STL" />
      </geometry>
      <material
        name="">
        <color
          rgba="0.792156862745098 0.819607843137255 0.933333333333333 1" />
      </material>
    </visual>
    <collision>
      <origin
        xyz="0 0 0"
        rpy="0 0 0" />
      <geometry>
        <mesh
          filename="package://carver_description/meshes/rear_right_wheel_Link.STL" />
      </geometry>
    </collision>
  </link>
  <joint
    name="base_rear_right_wheel_joint"
    type="continuous">
    <origin
      xyz="-0.636881075366491 -0.3955 -0.17"
      rpy="-1.5707963267949 0 0" />
    <parent
      link="base_link" />
    <child
      link="rear_right_wheel_Link" />
    <axis
      xyz="0 0 1" />
    <limit
      effort="100"
      velocity="100" />
  </joint>
  <link
    name="rear_left_wheel_Link">
    <inertial>
      <origin
        xyz="-1.11022302462516E-16 -5.55111512312578E-17 -0.038"
        rpy="0 0 0" />
      <mass
        value="5.024500013847" />
      <inertia
        ixx="0.0459189311540779"
        ixy="-1.69340415001856E-17"
        ixz="-1.63413912841509E-20"
        iyy="0.0459189311540779"
        iyz="-3.03572667974688E-19"
        izz="0.0878937287146472" />
    </inertial>
    <visual>
      <origin
        xyz="0 0 0"
        rpy="0 0 0" />
      <geometry>
        <mesh
          filename="package://carver_description/meshes/rear_left_wheel_Link.STL" />
      </geometry>
      <material
        name="">
        <color
          rgba="0.792156862745098 0.819607843137255 0.933333333333333 1" />
      </material>
    </visual>
    <collision>
      <origin
        xyz="0 0 0"
        rpy="0 0 0" />
      <geometry>
        <mesh
          filename="package://carver_description/meshes/rear_left_wheel_Link.STL" />
      </geometry>
    </collision>
  </link>
  <joint
    name="base_rear_left_wheel_joint"
    type="continuous">
    <origin
      xyz="-0.636881075366491 0.3955 -0.17"
      rpy="-1.5707963267949 0 0" />
    <parent
      link="base_link" />
    <child
      link="rear_left_wheel_Link" />
    <axis
      xyz="0 0 -1" />
    <limit
      effort="100"
      velocity="100" />
  </joint>
  <link
    name="C16_Link">
    <inertial>
      <origin
        xyz="-0.000884749784486272 1.07190634318916E-07 0.00143612694648154"
        rpy="0 0 0" />
      <mass
        value="0.663324628749119" />
      <inertia
        ixx="0.000791421263365419"
        ixy="1.38226469561801E-09"
        ixz="-5.15681751766987E-06"
        iyy="0.000800507843146539"
        iyz="1.51968163394474E-09"
        izz="0.000866550903215115" />
    </inertial>
    <visual>
      <origin
        xyz="0 0 0"
        rpy="0 0 0" />
      <geometry>
        <mesh
          filename="package://carver_description/meshes/C16_Link.STL" />
      </geometry>
      <material
        name="">
        <color
          rgba="0.792156862745098 0.819607843137255 0.933333333333333 1" />
      </material>
    </visual>
    <collision>
      <origin
        xyz="0 0 0"
        rpy="0 0 0" />
      <geometry>
        <mesh
          filename="package://carver_description/meshes/C16_Link.STL" />
      </geometry>
    </collision>
  </link>
  <joint
    name="base_C16_joint"
    type="fixed">
    <origin
      xyz="0.237767026438175 0 1.56788196587258"
      rpy="0 0 0" />
    <parent
      link="base_link" />
    <child
      link="C16_Link" />
    <axis
      xyz="0 0 0" />
  </joint>
  <link
    name="T265_Link">
    <inertial>
      <origin
        xyz="-0.00700393876078764 -0.00123869269730153 -9.55081819836723E-06"
        rpy="0 0 0" />
      <mass
        value="0.0153522629827051" />
      <inertia
        ixx="1.39361946580663E-05"
        ixy="1.34672770580705E-08"
        ixz="1.90513550220797E-09"
        iyy="9.41413823470546E-07"
        iyz="4.36674998271113E-09"
        izz="1.32399745394749E-05" />
    </inertial>
    <visual>
      <origin
        xyz="0 0 0"
        rpy="0 0 0" />
      <geometry>
        <mesh
          filename="package://carver_description/meshes/T265_Link.STL" />
      </geometry>
      <material
        name="">
        <color
          rgba="0.752941176470588 0.752941176470588 0.752941176470588 1" />
      </material>
    </visual>
    <collision>
      <origin
        xyz="0 0 0"
        rpy="0 0 0" />
      <geometry>
        <mesh
          filename="package://carver_description/meshes/T265_Link.STL" />
      </geometry>
    </collision>
  </link>
  <joint
    name="base_T265_joint"
    type="fixed">
    <origin
      xyz="0.914568924633506 0.000699999999822833 0.423999999999455"
      rpy="0 0 0" />
    <parent
      link="base_link" />
    <child
      link="T265_Link" />
    <axis
      xyz="0 0 0" />
  </joint>
  <link
    name="L515_Link">
    <inertial>
      <origin
        xyz="-0.0138329335161044 0.000212766277086438 -0.0151333320329214"
        rpy="0 0 0" />
      <mass
        value="0.0519003008836609" />
      <inertia
        ixx="2.29233885806648E-05"
        ixy="-3.43966785553651E-08"
        ixz="-9.60811102901314E-09"
        iyy="1.23501086319318E-05"
        iyz="1.7364371003412E-07"
        izz="1.35094237257256E-05" />
    </inertial>
    <visual>
      <origin
        xyz="0 0 0"
        rpy="0 0 0" />
      <geometry>
        <mesh
          filename="package://carver_description/meshes/L515_Link.STL" />
      </geometry>
      <material
        name="">
        <color
          rgba="0.752941176470588 0.752941176470588 0.752941176470588 1" />
      </material>
    </visual>
    <collision>
      <origin
        xyz="0 0 0"
        rpy="0 0 0" />
      <geometry>
        <mesh
          filename="package://carver_description/meshes/L515_Link.STL" />
      </geometry>
    </collision>
  </link>
  <joint
    name="base_L515_joint"
    type="fixed">
    <origin
      xyz="0.926668924633506 -1.17161568835617E-05 0.153229231648557"
      rpy="0 0 0" />
    <parent
      link="base_link" />
    <child
      link="L515_Link" />
    <axis
      xyz="0 0 0" />
  </joint>
  <link
    name="LD_SICK_Link">
    <inertial>
      <origin
        xyz="-0.0476495449150263 3.70691329259393E-07 -4.4470215562753E-06"
        rpy="0 0 0" />
      <mass
        value="0.911976961838327" />
      <inertia
        ixx="0.00155787250018402"
        ixy="-1.82431705523697E-09"
        ixz="2.07922879374534E-08"
        iyy="0.00127638625018271"
        iyz="-1.43394136853219E-08"
        izz="0.00165040465761084" />
    </inertial>
    <visual>
      <origin
        xyz="0 0 0"
        rpy="0 0 0" />
      <geometry>
        <mesh
          filename="package://carver_description/meshes/LD_SICK_Link.STL" />
      </geometry>
      <material
        name="">
        <color
          rgba="0.792156862745098 0.819607843137255 0.933333333333333 1" />
      </material>
    </visual>
    <collision>
      <origin
        xyz="0 0 0"
        rpy="0 0 0" />
      <geometry>
        <mesh
          filename="package://carver_description/meshes/LD_SICK_Link.STL" />
      </geometry>
    </collision>
  </link>
  <joint
    name="base_LD_SICK_joint"
    type="fixed">
    <origin
      xyz="1.04931892463351 0 -0.0799999999999999"
      rpy="0 0 0" />
    <parent
      link="base_link" />
    <child
      link="LD_SICK_Link" />
    <axis
      xyz="0 0 0" />
  </joint>
  <link
    name="RPLIDAR_F_Link">
    <inertial>
      <origin
        xyz="-0.0161960491203498 -9.31983563964844E-05 -0.016678862350989"
        rpy="0 0 0" />
      <mass
        value="0.0327576849285805" />
      <inertia
        ixx="1.08457089649924E-05"
        ixy="-2.43584002034583E-09"
        ixz="1.62318211761312E-08"
        iyy="1.07873373896528E-05"
        iyz="-4.20831743894438E-09"
        izz="1.96375495605278E-05" />
    </inertial>
    <visual>
      <origin
        xyz="0 0 0"
        rpy="0 0 0" />
      <geometry>
        <mesh
          filename="package://carver_description/meshes/RPLIDAR_F_Link.STL" />
      </geometry>
      <material
        name="">
        <color
          rgba="0.4 0.4 0.4 1" />
      </material>
    </visual>
    <collision>
      <origin
        xyz="0 0 0"
        rpy="0 0 0" />
      <geometry>
        <mesh
          filename="package://carver_description/meshes/RPLIDAR_F_Link.STL" />
      </geometry>
    </collision>
  </link>
  <joint
    name="base_RPLIDAR_F_joint"
    type="fixed">
    <origin
      xyz="1.01210078117234 0.385500000000004 0.0862783318747024"
      rpy="0 0 0" />
    <parent
      link="base_link" />
    <child
      link="RPLIDAR_F_Link" />
    <axis
      xyz="0 0 0" />
  </joint>
  <link
    name="RPLIDAR_B_Link">
    <inertial>
      <origin
        xyz="0.0161960490985061 9.31983911913181E-05 -0.0166788622788748"
        rpy="0 0 0" />
      <mass
        value="0.0327576855940814" />
      <inertia
        ixx="1.08457089721965E-05"
        ixy="-2.43583783710561E-09"
        ixz="-1.62318204488479E-08"
        iyy="1.07873373962556E-05"
        iyz="4.2083164592071E-09"
        izz="1.963754956115E-05" />
    </inertial>
    <visual>
      <origin
        xyz="0 0 0"
        rpy="0 0 0" />
      <geometry>
        <mesh
          filename="package://carver_description/meshes/RPLIDAR_B_Link.STL" />
      </geometry>
      <material
        name="">
        <color
          rgba="0.4 0.4 0.4 1" />
      </material>
    </visual>
    <collision>
      <origin
        xyz="0 0 0"
        rpy="0 0 0" />
      <geometry>
        <mesh
          filename="package://carver_description/meshes/RPLIDAR_B_Link.STL" />
      </geometry>
    </collision>
  </link>
  <joint
    name="base_RPLIDAR_joint"
    type="fixed">
    <origin
      xyz="-1.00986293190532 -0.385500000000006 0.0862783318747023"
      rpy="0 0 0" />
    <parent
      link="base_link" />
    <child
      link="RPLIDAR_B_Link" />
    <axis
      xyz="0 0 0" />
  </joint>
</robot>