<?xml version="1.0" encoding="utf-8"?>
<!-- This URDF was automatically created by SolidWorks to URDF Exporter! Originally created by Stephen Brawner (brawner@gmail.com) 
     Commit Version: 1.6.0-4-g7f85cfe  Build Version: 1.6.7995.38578
     For more information, please see http://wiki.ros.org/sw_urdf_exporter -->
<robot
  name="carver_description">
  
  <link name="world"></link>
  
  <link
    name="base_link">
    <inertial>
      <origin
        xyz="0.0761946454551612 -0.000112126182761479 0.181680737508157"
        rpy="0 0 0" />
      <mass
        value="223.870769479693" />
      <inertia
        ixx="11.099084348426"
        ixy="2.54469100809526E-05"
        ixz="-0.00666553489243874"
        iyy="35.71932851466"
        iyz="-0.00132352549971649"
        izz="40.757751944957" />
    </inertial>
    <visual>
      <origin
        xyz="0 0 0"
        rpy="0 0 0" />
      <geometry>
        <mesh
          filename="package://carver_description/meshes/base_link.STL" />
      </geometry>
      <material
        name="">
        <color
          rgba="0.792156862745098 0.819607843137255 0.933333333333333 1" />
      </material>
    </visual>
    <collision>
      <origin
        xyz="0 0 0"
        rpy="0 0 0" />
      <geometry>
        <mesh
          filename="package://carver_description/meshes/base_link.STL" />
      </geometry>
    </collision>
  </link>
  
  <joint name="world_base_joint" type="fixed">
    <parent link="world" /> 
    <child link="base_link" />
    <origin xyz="0 0 0.345" rpy="0 0 0" />
  </joint>
  
  <link
    name="front_right_sterring_Link">
    <inertial>
      <origin
        xyz="-6.87012402522669E-09 3.51066137271872E-09 -0.0112499999237069"
        rpy="0 0 0" />
      <mass
        value="0.0307417074716638" />
      <inertia
        ixx="5.15827058483555E-06"
        ixy="2.87694711205719E-08"
        ixz="-2.37787643316582E-12"
        iyy="5.94711293506547E-06"
        iyz="1.79592218418332E-13"
        izz="8.17709432093611E-06" />
    </inertial>
    <visual>
      <origin
        xyz="0 0 0"
        rpy="0 0 0" />
      <geometry>
        <mesh
          filename="package://carver_description/meshes/front_right_sterring_Link.STL" />
      </geometry>
      <material
        name="">
        <color
          rgba="0.792156862745098 0.819607843137255 0.933333333333333 1" />
      </material>
    </visual>
    <collision>
      <origin
        xyz="0 0 0"
        rpy="0 0 0" />
      <geometry>
        <mesh
          filename="package://carver_description/meshes/front_right_sterring_Link.STL" />
      </geometry>
    </collision>
  </link>
  <joint
    name="base_front_right_sterring_joint"
    type="revolute">
    <origin
      xyz="0.639118924633511 -0.284499999999994 -0.158749999999999"
      rpy="0 0 0" />
    <parent
      link="base_link" />
    <child
      link="front_right_sterring_Link" />
    <axis
      xyz="0 0 -1" />
    <limit
      lower="-3.14"
      upper="3.14"
      effort="100"
      velocity="100" />
  </joint>
  <link
    name="front_right_wheel_Link">
    <inertial>
      <origin
        xyz="0.00138386531093282 8.32667268468867E-17 0.0379747931765428"
        rpy="0 0 0" />
      <mass
        value="5.024500013847" />
      <inertia
        ixx="0.0459745995956163"
        ixy="8.99074949195895E-19"
        ixz="0.00152760354434749"
        iyy="0.0459189311540779"
        iyz="2.24551267593524E-18"
        izz="0.0878380602731089" />
    </inertial>
    <visual>
      <origin
        xyz="0 0 0"
        rpy="0 0 0" />
      <geometry>
        <mesh
          filename="package://carver_description/meshes/front_right_wheel_Link.STL" />
      </geometry>
      <material
        name="">
        <color
          rgba="0.792156862745098 0.819607843137255 0.933333333333333 1" />
      </material>
    </visual>
    <collision>
      <origin
        xyz="0 0 0"
        rpy="0 0 0" />
      <geometry>
        <mesh
          filename="package://carver_description/meshes/front_right_wheel_Link.STL" />
      </geometry>
    </collision>
  </link>
  <joint
    name="front_right_steering_front_right_wheel_joint"
    type="continuous">
    <origin
      xyz="-0.00404234340824972 -0.110926369542007 -0.0112500000000002"
      rpy="-1.5707963267949 0 0" />
    <parent
      link="front_right_sterring_Link" />
    <child
      link="front_right_wheel_Link" />
    <axis
      xyz="0.036417508182449 0 0.999336662540598" />
    <limit
      effort="100"
      velocity="100" />
  </joint>
  <link
    name="front_left_sterring_Link">
    <inertial>
      <origin
        xyz="7.10743075504894E-09 -3.0012958229797E-09 -0.0112499999237069"
        rpy="0 0 0" />
      <mass
        value="0.0307417074716638" />
      <inertia
        ixx="5.15827283476504E-06"
        ixy="-2.88003004005144E-08"
        ixz="2.38464111309773E-12"
        iyy="5.94711068513598E-06"
        iyz="-6.03807311086712E-15"
        izz="8.17709432093612E-06" />
    </inertial>
    <visual>
      <origin
        xyz="0 0 0"
        rpy="0 0 0" />
      <geometry>
        <mesh
          filename="package://carver_description/meshes/front_left_sterring_Link.STL" />
      </geometry>
      <material
        name="">
        <color
          rgba="0.792156862745098 0.819607843137255 0.933333333333333 1" />
      </material>
    </visual>
    <collision>
      <origin
        xyz="0 0 0"
        rpy="0 0 0" />
      <geometry>
        <mesh
          filename="package://carver_description/meshes/front_left_sterring_Link.STL" />
      </geometry>
    </collision>
  </link>
  <joint
    name="base_front_left_sterring_joint"
    type="revolute">
    <origin
      xyz="0.639118924633511 0.284499999999994 -0.158749999999999"
      rpy="0 0 0" />
    <parent
      link="base_link" />
    <child
      link="front_left_sterring_Link" />
    <axis
      xyz="0 0 -1" />
    <limit
      lower="-3.14"
      upper="3.14"
      effort="100"
      velocity="100" />
  </joint>
  <link
    name="front_left_wheel_Link">
    <inertial>
      <origin
        xyz="0.00138386531093293 1.11022302462516E-16 -0.0379747931765427"
        rpy="0 0 0" />
      <mass
        value="5.02450001384701" />
      <inertia
        ixx="0.0459745995956163"
        ixy="5.09543257332576E-19"
        ixz="-0.00152760354434749"
        iyy="0.0459189311540779"
        iyz="-2.42198483355528E-18"
        izz="0.0878380602731089" />
    </inertial>
    <visual>
      <origin
        xyz="0 0 0"
        rpy="0 0 0" />
      <geometry>
        <mesh
          filename="package://carver_description/meshes/front_left_wheel_Link.STL" />
      </geometry>
      <material
        name="">
        <color
          rgba="0.792156862745098 0.819607843137255 0.933333333333333 1" />
      </material>
    </visual>
    <collision>
      <origin
        xyz="0 0 0"
        rpy="0 0 0" />
      <geometry>
        <mesh
          filename="package://carver_description/meshes/front_left_wheel_Link.STL" />
      </geometry>
    </collision>
  </link>
  <joint
    name="front_left_steering_front_left_wheel_joint"
    type="continuous">
    <origin
      xyz="-0.00404234340824972 0.110926369542007 -0.0112500000000002"
      rpy="-1.5707963267949 0 0" />
    <parent
      link="front_left_sterring_Link" />
    <child
      link="front_left_wheel_Link" />
    <axis
      xyz="0.036417508182449 0 -0.999336662540598" />
    <limit
      effort="100"
      velocity="100" />
  </joint>
  <link
    name="rear_right_wheel_Link">
    <inertial>
      <origin
        xyz="-2.22044604925031E-16 -5.55111512312578E-17 0.0379999999999999"
        rpy="0 0 0" />
      <mass
        value="5.024500013847" />
      <inertia
        ixx="0.0459189311540779"
        ixy="-1.57627537528104E-17"
        ixz="1.54321261345797E-19"
        iyy="0.045918931154078"
        iyz="2.36027092222276E-19"
        izz="0.0878937287146473" />
    </inertial>
    <visual>
      <origin
        xyz="0 0 0"
        rpy="0 0 0" />
      <geometry>
        <mesh
          filename="package://carver_description/meshes/rear_right_wheel_Link.STL" />
      </geometry>
      <material
        name="">
        <color
          rgba="0.792156862745098 0.819607843137255 0.933333333333333 1" />
      </material>
    </visual>
    <collision>
      <origin
        xyz="0 0 0"
        rpy="0 0 0" />
      <geometry>
        <mesh
          filename="package://carver_description/meshes/rear_right_wheel_Link.STL" />
      </geometry>
    </collision>
  </link>
  <joint
    name="base_rear_right_wheel_joint"
    type="continuous">
    <origin
      xyz="-0.636881075366491 -0.3955 -0.17"
      rpy="-1.5707963267949 0 0" />
    <parent
      link="base_link" />
    <child
      link="rear_right_wheel_Link" />
    <axis
      xyz="0 0 1" />
    <limit
      effort="100"
      velocity="100" />
  </joint>
  <link
    name="rear_left_wheel_Link">
    <inertial>
      <origin
        xyz="-1.11022302462516E-16 -5.55111512312578E-17 -0.038"
        rpy="0 0 0" />
      <mass
        value="5.024500013847" />
      <inertia
        ixx="0.0459189311540779"
        ixy="-1.6940658945086E-17"
        ixz="-5.03700276956107E-20"
        iyy="0.0459189311540779"
        iyz="-2.73208875783828E-19"
        izz="0.0878937287146472" />
    </inertial>
    <visual>
      <origin
        xyz="0 0 0"
        rpy="0 0 0" />
      <geometry>
        <mesh
          filename="package://carver_description/meshes/rear_left_wheel_Link.STL" />
      </geometry>
      <material
        name="">
        <color
          rgba="0.792156862745098 0.819607843137255 0.933333333333333 1" />
      </material>
    </visual>
    <collision>
      <origin
        xyz="0 0 0"
        rpy="0 0 0" />
      <geometry>
        <mesh
          filename="package://carver_description/meshes/rear_left_wheel_Link.STL" />
      </geometry>
    </collision>
  </link>
  <joint
    name="base_rear_left_wheel_joint"
    type="continuous">
    <origin
      xyz="-0.636881075366491 0.3955 -0.17"
      rpy="-1.5707963267949 0 0" />
    <parent
      link="base_link" />
    <child
      link="rear_left_wheel_Link" />
    <axis
      xyz="0 0 -1" />
    <limit
      effort="100"
      velocity="100" />
  </joint>
  <link
    name="C16_Link">
    <inertial>
      <origin
        xyz="-0.000884749784506395 1.07190642272926E-07 0.00143612694647377"
        rpy="0 0 0" />
      <mass
        value="0.663324628749119" />
      <inertia
        ixx="0.000791421263365419"
        ixy="1.38226469562435E-09"
        ixz="-5.15681751766988E-06"
        iyy="0.000800507843146539"
        iyz="1.51968163394233E-09"
        izz="0.000866550903215115" />
    </inertial>
    <visual>
      <origin
        xyz="0 0 0"
        rpy="0 0 0" />
      <geometry>
        <mesh
          filename="package://carver_description/meshes/C16_Link.STL" />
      </geometry>
      <material
        name="">
        <color
          rgba="0.792156862745098 0.819607843137255 0.933333333333333 1" />
      </material>
    </visual>
    <collision>
      <origin
        xyz="0 0 0"
        rpy="0 0 0" />
      <geometry>
        <mesh
          filename="package://carver_description/meshes/C16_Link.STL" />
      </geometry>
    </collision>
  </link>
  <joint
    name="base_C16_joint"
    type="fixed">
    <origin
      xyz="0.237767026438191 0 1.56788196587259"
      rpy="0 0 0" />
    <parent
      link="base_link" />
    <child
      link="C16_Link" />
    <axis
      xyz="0 0 0" />
  </joint>
  <link
    name="T265_Link">
    <inertial>
      <origin
        xyz="-0.00700393876081729 -0.00123869269728773 -9.55081819781212E-06"
        rpy="0 0 0" />
      <mass
        value="0.0153522629829022" />
      <inertia
        ixx="1.39361946583913E-05"
        ixy="1.34672770579496E-08"
        ixz="1.90513550225716E-09"
        iyy="9.41413823478556E-07"
        iyz="4.36675000376219E-09"
        izz="1.32399745397931E-05" />
    </inertial>
    <visual>
      <origin
        xyz="0 0 0"
        rpy="0 0 0" />
      <geometry>
        <mesh
          filename="package://carver_description/meshes/T265_Link.STL" />
      </geometry>
      <material
        name="">
        <color
          rgba="0.752941176470588 0.752941176470588 0.752941176470588 1" />
      </material>
    </visual>
    <collision>
      <origin
        xyz="0 0 0"
        rpy="0 0 0" />
      <geometry>
        <mesh
          filename="package://carver_description/meshes/T265_Link.STL" />
      </geometry>
    </collision>
  </link>
  <joint
    name="base_T265_joint"
    type="fixed">
    <origin
      xyz="0.914568924633506 0.000699999999822833 0.423999999999455"
      rpy="0 0 0" />
    <parent
      link="base_link" />
    <child
      link="T265_Link" />
    <axis
      xyz="0 0 0" />
  </joint>
  <link
    name="L515_Link">
    <inertial>
      <origin
        xyz="-0.0138329335160924 0.000212766276144194 -0.0151333320328252"
        rpy="0 0 0" />
      <mass
        value="0.0519003008833496" />
      <inertia
        ixx="2.29233885806633E-05"
        ixy="-3.43966785553732E-08"
        ixz="-9.60811102903891E-09"
        iyy="1.23501086319306E-05"
        iyz="1.73643710033919E-07"
        izz="1.35094237257254E-05" />
    </inertial>
    <visual>
      <origin
        xyz="0 0 0"
        rpy="0 0 0" />
      <geometry>
        <mesh
          filename="package://carver_description/meshes/L515_Link.STL" />
      </geometry>
      <material
        name="">
        <color
          rgba="0.752941176470588 0.752941176470588 0.752941176470588 1" />
      </material>
    </visual>
    <collision>
      <origin
        xyz="0 0 0"
        rpy="0 0 0" />
      <geometry>
        <mesh
          filename="package://carver_description/meshes/L515_Link.STL" />
      </geometry>
    </collision>
  </link>
  <joint
    name="base_L515_joint"
    type="fixed">
    <origin
      xyz="0.929717002207267 -1.17161560733146E-05 -0.0149951470092575"
      rpy="0 0 0" />
    <parent
      link="base_link" />
    <child
      link="L515_Link" />
    <axis
      xyz="0 0 0" />
  </joint>
  <link
    name="LD_SICK_Link">
    <inertial>
      <origin
        xyz="-0.0476495449150333 3.70691349273247E-07 -4.44702155605325E-06"
        rpy="0 0 0" />
      <mass
        value="0.911976961838331" />
      <inertia
        ixx="0.00155787250018403"
        ixy="-1.82431705414264E-09"
        ixz="2.07922879363463E-08"
        iyy="0.00127638625018272"
        iyz="-1.43394136804659E-08"
        izz="0.00165040465761085" />
    </inertial>
    <visual>
      <origin
        xyz="0 0 0"
        rpy="0 0 0" />
      <geometry>
        <mesh
          filename="package://carver_description/meshes/LD_SICK_Link.STL" />
      </geometry>
      <material
        name="">
        <color
          rgba="0.792156862745098 0.819607843137255 0.933333333333333 1" />
      </material>
    </visual>
    <collision>
      <origin
        xyz="0 0 0"
        rpy="0 0 0" />
      <geometry>
        <mesh
          filename="package://carver_description/meshes/LD_SICK_Link.STL" />
      </geometry>
    </collision>
  </link>
  <joint
    name="base_LD_SICK_joint"
    type="fixed">
    <origin
      xyz="0.942318924633513 0 0.215"
      rpy="0 0 0" />
    <parent
      link="base_link" />
    <child
      link="LD_SICK_Link" />
    <axis
      xyz="0 0 0" />
  </joint>
  <link
    name="RPLIDAR_LF_Link">
    <inertial>
      <origin
        xyz="-0.0161960491202214 -9.3198357016322E-05 -0.0166788623509912"
        rpy="0 0 0" />
      <mass
        value="0.0327576849285788" />
      <inertia
        ixx="1.08457089649951E-05"
        ixy="-2.43584020511913E-09"
        ixz="1.62318211728069E-08"
        iyy="1.07873373896473E-05"
        iyz="-4.20831726037415E-09"
        izz="1.96375495605249E-05" />
    </inertial>
    <visual>
      <origin
        xyz="0 0 0"
        rpy="0 0 0" />
      <geometry>
        <mesh
          filename="package://carver_description/meshes/RPLIDAR_LF_Link.STL" />
      </geometry>
      <material
        name="">
        <color
          rgba="0.4 0.4 0.4 1" />
      </material>
    </visual>
    <collision>
      <origin
        xyz="0 0 0"
        rpy="0 0 0" />
      <geometry>
        <mesh
          filename="package://carver_description/meshes/RPLIDAR_LF_Link.STL" />
      </geometry>
    </collision>
  </link>
  <joint
    name="base_RPLIDAR_LF_joint"
    type="fixed">
    <origin
      xyz="0.912928672596467 0.374905020086834 0.0854783318747023"
      rpy="0 0 0" />
    <parent
      link="base_link" />
    <child
      link="RPLIDAR_LF_Link" />
    <axis
      xyz="0 0 0" />
  </joint>
  <link
    name="RPLIDAR_RB_Link">
    <inertial>
      <origin
        xyz="0.0113864348242855 0.0115182368440745 -0.0166788620431012"
        rpy="0 0 0" />
      <mass
        value="0.0327576843712563" />
      <inertia
        ixx="1.0818959032604E-05"
        ixy="2.91857914862337E-08"
        ixz="-1.4453365941237E-08"
        iyy="1.08140873423105E-05"
        iyz="-8.50190782091936E-09"
        izz="1.96375495817862E-05" />
    </inertial>
    <visual>
      <origin
        xyz="0 0 0"
        rpy="0 0 0" />
      <geometry>
        <mesh
          filename="package://carver_description/meshes/RPLIDAR_RB_Link.STL" />
      </geometry>
      <material
        name="">
        <color
          rgba="0.4 0.4 0.4 1" />
      </material>
    </visual>
    <collision>
      <origin
        xyz="0 0 0"
        rpy="0 0 0" />
      <geometry>
        <mesh
          filename="package://carver_description/meshes/RPLIDAR_RB_Link.STL" />
      </geometry>
    </collision>
  </link>
  <joint
    name="base_RPLIDAR_RB_joint"
    type="fixed">
    <origin
      xyz="-0.866459374365379 -0.3462959068844 0.0854783318747023"
      rpy="0 0 0" />
    <parent
      link="base_link" />
    <child
      link="RPLIDAR_RB_Link" />
    <axis
      xyz="0 0 0" />
  </joint>
  <link
    name="RPLIDAR_LB_Link">
    <inertial>
      <origin
        xyz="0.0140727894506423 -0.00801731234829417 -0.0166788621810948"
        rpy="0 0 0" />
      <mass
        value="0.0327576849816352" />
      <inertia
        ixx="1.08290065770166E-05"
        ixy="-2.64935628686228E-08"
        ixz="-1.19530169067728E-08"
        iyy="1.08040398040207E-05"
        iyz="1.17604200923437E-08"
        izz="1.96375495880274E-05" />
    </inertial>
    <visual>
      <origin
        xyz="0 0 0"
        rpy="0 0 0" />
      <geometry>
        <mesh
          filename="package://carver_description/meshes/RPLIDAR_LB_Link.STL" />
      </geometry>
      <material
        name="">
        <color
          rgba="0.4 0.4 0.4 1" />
      </material>
    </visual>
    <collision>
      <origin
        xyz="0 0 0"
        rpy="0 0 0" />
      <geometry>
        <mesh
          filename="package://carver_description/meshes/RPLIDAR_LB_Link.STL" />
      </geometry>
    </collision>
  </link>
  <joint
    name="base_RPLIDAR_LB_joint"
    type="fixed">
    <origin
      xyz="-0.894118330232296 0.316260936090295 0.0854783318747023"
      rpy="0 0 0" />
    <parent
      link="base_link" />
    <child
      link="RPLIDAR_LB_Link" />
    <axis
      xyz="0 0 0" />
  </joint>
  <link
    name="IMU_R_Link">
    <inertial>
      <origin
        xyz="0.000436358638966239 8.66736194121698E-05 -0.00106324875441705"
        rpy="0 0 0" />
      <mass
        value="0.000983130183652042" />
      <inertia
        ixx="2.7278081479223E-08"
        ixy="-1.86463715352959E-11"
        ixz="-1.8313575756947E-11"
        iyy="4.80453464098755E-08"
        iyz="1.81575171892466E-12"
        izz="7.48563776021962E-08" />
    </inertial>
    <visual>
      <origin
        xyz="0 0 0"
        rpy="0 0 0" />
      <geometry>
        <mesh
          filename="package://carver_description/meshes/IMU_R_Link.STL" />
      </geometry>
      <material
        name="">
        <color
          rgba="0.792156862745098 0.819607843137255 0.933333333333333 1" />
      </material>
    </visual>
    <collision>
      <origin
        xyz="0 0 0"
        rpy="0 0 0" />
      <geometry>
        <mesh
          filename="package://carver_description/meshes/IMU_R_Link.STL" />
      </geometry>
    </collision>
  </link>
  <joint
    name="base_IMU_R_joint"
    type="fixed">
    <origin
      xyz="0.0271694412238607 -0.0191012435918216 0.383"
      rpy="0 0 0" />
    <parent
      link="base_link" />
    <child
      link="IMU_R_Link" />
    <axis
      xyz="0 0 0" />
  </joint>
  <link
    name="IMU_L_Link">
    <inertial>
      <origin
        xyz="0.000436358638966235 8.66736194121559E-05 -0.00106324875441655"
        rpy="0 0 0" />
      <mass
        value="0.000983130183652038" />
      <inertia
        ixx="2.7278081479223E-08"
        ixy="-1.86463715354785E-11"
        ixz="-1.83135757570046E-11"
        iyy="4.80453464098757E-08"
        iyz="1.81575171892299E-12"
        izz="7.48563776021965E-08" />
    </inertial>
    <visual>
      <origin
        xyz="0 0 0"
        rpy="0 0 0" />
      <geometry>
        <mesh
          filename="package://carver_description/meshes/IMU_L_Link.STL" />
      </geometry>
      <material
        name="">
        <color
          rgba="0.792156862745098 0.819607843137255 0.933333333333333 1" />
      </material>
    </visual>
    <collision>
      <origin
        xyz="0 0 0"
        rpy="0 0 0" />
      <geometry>
        <mesh
          filename="package://carver_description/meshes/IMU_L_Link.STL" />
      </geometry>
    </collision>
  </link>
  <joint
    name="base_IMU_L_joint"
    type="fixed">
    <origin
      xyz="0.029419441223861 0.0191387564081886 0.383"
      rpy="0 0 0" />
    <parent
      link="base_link" />
    <child
      link="IMU_L_Link" />
    <axis
      xyz="0 0 0" />
  </joint>
</robot>
