<?xml version="1.0" encoding="utf-8"?>
<!-- This URDF was automatically created by SolidWorks to URDF Exporter! Originally created by Stephen Brawner (brawner@gmail.com) 
     Commit Version: 1.6.0-4-g7f85cfe  Build Version: 1.6.7995.38578
     For more information, please see http://wiki.ros.org/sw_urdf_exporter -->
<robot
  name="carver_description">

  <link name="world"></link>

  <link
    name="base_link">
    <inertial>
      <origin
        xyz="0.0774139032574961 -0.000614738170301796 0.182831184388341"
        rpy="0 0 0" />
      <mass
        value="224.416537318038" />
      <inertia
        ixx="11.1087441912722"
        ixy="-0.000143787949337605"
        ixz="-0.00666553671990693"
        iyy="35.7201566919953"
        iyz="-0.00132350955436533"
        izz="40.7666097109411" />
    </inertial>
    <visual>
      <origin
        xyz="0 0 0"
        rpy="0 0 0" />
      <geometry>
        <mesh
          filename="package://carver_description/meshes/base_link.STL" />
      </geometry>
      <material
        name="">
        <color
          rgba="0.792156862745098 0.819607843137255 0.933333333333333 1" />
      </material>
    </visual>
    <collision>
      <origin
        xyz="0 0 0"
        rpy="0 0 0" />
      <geometry>
        <mesh
          filename="package://carver_description/meshes/base_link.STL" />
      </geometry>
    </collision>
  </link>

  <joint name="world_base_joint" type="fixed">
    <parent link="world" /> 
    <child link="base_link" />
    <origin xyz="0 0 0.345" rpy="0 0 0" />
  </joint>

  <link
    name="front_right_sterring_Link">
    <inertial>
      <origin
        xyz="-6.87012402522669E-09 3.51066137271872E-09 -0.0112499999237069"
        rpy="0 0 0" />
      <mass
        value="0.0307417074716638" />
      <inertia
        ixx="5.15827058483555E-06"
        ixy="2.87694711205719E-08"
        ixz="-2.37787643332467E-12"
        iyy="5.94711293506547E-06"
        iyz="1.79592218413634E-13"
        izz="8.17709432093611E-06" />
    </inertial>
    <visual>
      <origin
        xyz="0 0 0"
        rpy="0 0 0" />
      <geometry>
        <mesh
          filename="package://carver_description/meshes/front_right_sterring_Link.STL" />
      </geometry>
      <material
        name="">
        <color
          rgba="0.792156862745098 0.819607843137255 0.933333333333333 1" />
      </material>
    </visual>
    <collision>
      <origin
        xyz="0 0 0"
        rpy="0 0 0" />
      <geometry>
        <mesh
          filename="package://carver_description/meshes/front_right_sterring_Link.STL" />
      </geometry>
    </collision>
  </link>
  <joint
    name="base_front_right_sterring_joint"
    type="revolute">
    <origin
      xyz="0.639118924633511 -0.284499999999994 -0.158749999999999"
      rpy="0 0 0" />
    <parent
      link="base_link" />
    <child
      link="front_right_sterring_Link" />
    <axis
      xyz="0 0 -1" />
    <limit
      lower="-3.14"
      upper="3.14"
      effort="100"
      velocity="100" />
  </joint>
  <link
    name="front_right_wheel_Link">
    <inertial>
      <origin
        xyz="0.0013839 8.3267E-17 0.037975"
        rpy="0 0 0" />
      <mass
        value="5.0245" />
      <inertia
        ixx="0.045975"
        ixy="8.7185E-19"
        ixz="0.0015276"
        iyy="0.045919"
        iyz="2.235E-18"
        izz="0.087838" />
    </inertial>
    <visual>
      <origin
        xyz="0 0 0"
        rpy="0 0 0" />
      <geometry>
        <mesh
          filename="package://carver_description/meshes/front_right_wheel_Link.STL" />
      </geometry>
      <material
        name="">
        <color
          rgba="0.79216 0.81961 0.93333 1" />
      </material>
    </visual>
    <collision>
      <origin
        xyz="0 0 0"
        rpy="0 0 0" />
      <geometry>
        <mesh
          filename="package://carver_description/meshes/front_right_wheel_Link.STL" />
      </geometry>
    </collision>
  </link>
  <joint
    name="front_right_steering_front_right_wheel_joint"
    type="continuous">
    <origin
      xyz="-0.00404234340824972 -0.110926369542007 -0.0112500000000002"
      rpy="-1.5707963267949 0 0" />
    <parent
      link="front_right_sterring_Link" />
    <child
      link="front_right_wheel_Link" />
    <axis
      xyz="0.036417508182449 0 0.999336662540598" />
    <limit
      effort="100"
      velocity="100" />
  </joint>
  <link
    name="front_left_sterring_Link">
    <inertial>
      <origin
        xyz="7.10743075504894E-09 -3.0012958229797E-09 -0.0112499999237069"
        rpy="0 0 0" />
      <mass
        value="0.0307417074716638" />
      <inertia
        ixx="5.15827283476504E-06"
        ixy="-2.88003004005144E-08"
        ixz="2.38464111325656E-12"
        iyy="5.94711068513598E-06"
        iyz="-6.03807310080527E-15"
        izz="8.17709432093612E-06" />
    </inertial>
    <visual>
      <origin
        xyz="0 0 0"
        rpy="0 0 0" />
      <geometry>
        <mesh
          filename="package://carver_description/meshes/front_left_sterring_Link.STL" />
      </geometry>
      <material
        name="">
        <color
          rgba="0.792156862745098 0.819607843137255 0.933333333333333 1" />
      </material>
    </visual>
    <collision>
      <origin
        xyz="0 0 0"
        rpy="0 0 0" />
      <geometry>
        <mesh
          filename="package://carver_description/meshes/front_left_sterring_Link.STL" />
      </geometry>
    </collision>
  </link>
  <joint
    name="base_front_left_sterring_joint"
    type="revolute">
    <origin
      xyz="0.639118924633511 0.284499999999994 -0.158749999999999"
      rpy="0 0 0" />
    <parent
      link="base_link" />
    <child
      link="front_left_sterring_Link" />
    <axis
      xyz="0 0 -1" />
    <limit
      lower="-3.14"
      upper="3.14"
      effort="100"
      velocity="100" />
  </joint>
  <link
    name="front_left_wheel_Link">
    <inertial>
      <origin
        xyz="0.00138386531093293 1.38777878078145E-16 -0.0379747931765427"
        rpy="0 0 0" />
      <mass
        value="5.02450001384701" />
      <inertia
        ixx="0.0459745995956163"
        ixy="6.3362034921553E-19"
        ixz="-0.00152760354434749"
        iyy="0.0459189311540779"
        iyz="-2.43821825307663E-18"
        izz="0.0878380602731089" />
    </inertial>
    <visual>
      <origin
        xyz="0 0 0"
        rpy="0 0 0" />
      <geometry>
        <mesh
          filename="package://carver_description/meshes/front_left_wheel_Link.STL" />
      </geometry>
      <material
        name="">
        <color
          rgba="0.792156862745098 0.819607843137255 0.933333333333333 1" />
      </material>
    </visual>
    <collision>
      <origin
        xyz="0 0 0"
        rpy="0 0 0" />
      <geometry>
        <mesh
          filename="package://carver_description/meshes/front_left_wheel_Link.STL" />
      </geometry>
    </collision>
  </link>
  <joint
    name="front_left_steering_front_left_wheel_joint"
    type="continuous">
    <origin
      xyz="-0.0040423 0.11093 -0.01125"
      rpy="-1.5708 0 0" />
    <parent
      link="front_left_sterring_Link" />
    <child
      link="front_left_wheel_Link" />
    <axis
      xyz="0.036418 0 -0.99934" />
    <limit
      effort="100"
      velocity="100" />
  </joint>
  <link
    name="rear_right_wheel_Link">
    <inertial>
      <origin
        xyz="-1.11022302462516E-16 -8.32667268468867E-17 0.0379999999999999"
        rpy="0 0 0" />
      <mass
        value="5.024500013847" />
      <inertia
        ixx="0.0459189311540779"
        ixy="-1.56864463413024E-17"
        ixz="1.52096771869045E-19"
        iyy="0.045918931154078"
        iyz="2.66081321145035E-19"
        izz="0.0878937287146473" />
    </inertial>
    <visual>
      <origin
        xyz="0 0 0"
        rpy="0 0 0" />
      <geometry>
        <mesh
          filename="package://carver_description/meshes/rear_right_wheel_Link.STL" />
      </geometry>
      <material
        name="">
        <color
          rgba="0.792156862745098 0.819607843137255 0.933333333333333 1" />
      </material>
    </visual>
    <collision>
      <origin
        xyz="0 0 0"
        rpy="0 0 0" />
      <geometry>
        <mesh
          filename="package://carver_description/meshes/rear_right_wheel_Link.STL" />
      </geometry>
    </collision>
  </link>
  <joint
    name="base_rear_right_wheel_joint"
    type="continuous">
    <origin
      xyz="-0.63688 -0.3955 -0.17"
      rpy="-1.5708 0 0" />
    <parent
      link="base_link" />
    <child
      link="rear_right_wheel_Link" />
    <axis
      xyz="0 0 1" />
    <limit
      effort="100"
      velocity="100" />
  </joint>
  <link
    name="rear_left_wheel_Link">
    <inertial>
      <origin
        xyz="-1.11022302462516E-16 -5.55111512312578E-17 -0.038"
        rpy="0 0 0" />
      <mass
        value="5.024500013847" />
      <inertia
        ixx="0.0459189311540779"
        ixy="-1.69724941490129E-17"
        ixz="-1.63413912841507E-20"
        iyy="0.0459189311540779"
        iyz="-3.03572667974688E-19"
        izz="0.0878937287146472" />
    </inertial>
    <visual>
      <origin
        xyz="0 0 0"
        rpy="0 0 0" />
      <geometry>
        <mesh
          filename="package://carver_description/meshes/rear_left_wheel_Link.STL" />
      </geometry>
      <material
        name="">
        <color
          rgba="0.792156862745098 0.819607843137255 0.933333333333333 1" />
      </material>
    </visual>
    <collision>
      <origin
        xyz="0 0 0"
        rpy="0 0 0" />
      <geometry>
        <mesh
          filename="package://carver_description/meshes/rear_left_wheel_Link.STL" />
      </geometry>
    </collision>
  </link>
  <joint
    name="base_rear_left_wheel_joint"
    type="continuous">
    <origin
      xyz="-0.63688 0.3955 -0.17"
      rpy="-1.5708 0 0" />
    <parent
      link="base_link" />
    <child
      link="rear_left_wheel_Link" />
    <axis
      xyz="0 0 -1" />
    <limit
      effort="100"
      velocity="100" />
  </joint>
  <link
    name="C16_Link">
    <inertial>
      <origin
        xyz="-0.00088474978448877 1.07190642272392E-07 0.00143612694647577"
        rpy="0 0 0" />
      <mass
        value="0.663324628749119" />
      <inertia
        ixx="0.000791421263365419"
        ixy="1.38226469561758E-09"
        ixz="-5.15681751766988E-06"
        iyy="0.000800507843146539"
        iyz="1.51968163395452E-09"
        izz="0.000866550903215115" />
    </inertial>
    <visual>
      <origin
        xyz="0 0 0"
        rpy="0 0 0" />
      <geometry>
        <mesh
          filename="package://carver_description/meshes/C16_Link.STL" />
      </geometry>
      <material
        name="">
        <color
          rgba="0.792156862745098 0.819607843137255 0.933333333333333 1" />
      </material>
    </visual>
    <collision>
      <origin
        xyz="0 0 0"
        rpy="0 0 0" />
      <geometry>
        <mesh
          filename="package://carver_description/meshes/C16_Link.STL" />
      </geometry>
    </collision>
  </link>
  <joint
    name="base_C16_joint"
    type="fixed">
    <origin
      xyz="0.23777 0 1.5679"
      rpy="0 0 0" />
    <parent
      link="base_link" />
    <child
      link="C16_Link" />
    <axis
      xyz="0 0 0" />
  </joint>
  <link
    name="T265_Link">
    <inertial>
      <origin
        xyz="-0.00700393876080008 -0.00123869269728641 -9.55081819797865E-06"
        rpy="0 0 0" />
      <mass
        value="0.015352262982903" />
      <inertia
        ixx="1.39361946583924E-05"
        ixy="1.34672770579493E-08"
        ixz="1.90513550223787E-09"
        iyy="9.41413823478597E-07"
        iyz="4.36675000350989E-09"
        izz="1.32399745397941E-05" />
    </inertial>
    <visual>
      <origin
        xyz="0 0 0"
        rpy="0 0 0" />
      <geometry>
        <mesh
          filename="package://carver_description/meshes/T265_Link.STL" />
      </geometry>
      <material
        name="">
        <color
          rgba="0.752941176470588 0.752941176470588 0.752941176470588 1" />
      </material>
    </visual>
    <collision>
      <origin
        xyz="0 0 0"
        rpy="0 0 0" />
      <geometry>
        <mesh
          filename="package://carver_description/meshes/T265_Link.STL" />
      </geometry>
    </collision>
  </link>
  <joint
    name="base_T265_joint"
    type="fixed">
    <origin
      xyz="0.91457 0.0007 0.424"
      rpy="0 0 0" />
    <parent
      link="base_link" />
    <child
      link="T265_Link" />
    <axis
      xyz="0 0 0" />
  </joint>
  <link
    name="L515_Link">
    <inertial>
      <origin
        xyz="-0.0138329335160924 0.000212766276144194 -0.0151333320328252"
        rpy="0 0 0" />
      <mass
        value="0.0519003008833496" />
      <inertia
        ixx="2.29233885806633E-05"
        ixy="-3.4396678555373E-08"
        ixz="-9.60811102903942E-09"
        iyy="1.23501086319306E-05"
        iyz="1.73643710033919E-07"
        izz="1.35094237257254E-05" />
    </inertial>
    <visual>
      <origin
        xyz="0 0 0"
        rpy="0 0 0" />
      <geometry>
        <mesh
          filename="package://carver_description/meshes/L515_Link.STL" />
      </geometry>
      <material
        name="">
        <color
          rgba="0.752941176470588 0.752941176470588 0.752941176470588 1" />
      </material>
    </visual>
    <collision>
      <origin
        xyz="0 0 0"
        rpy="0 0 0" />
      <geometry>
        <mesh
          filename="package://carver_description/meshes/L515_Link.STL" />
      </geometry>
    </collision>
  </link>
  <joint
    name="base_L515_joint"
    type="fixed">
    <origin
      xyz="0.92972 -1.1716E-05 -0.014995"
      rpy="0 0 0" />
    <parent
      link="base_link" />
    <child
      link="L515_Link" />
    <axis
      xyz="0 0 0" />
  </joint>
  <link
    name="LD_SICK_Link">
    <inertial>
      <origin
        xyz="-0.0476495449150156 3.70691349517161E-07 -4.44702155646959E-06"
        rpy="0 0 0" />
      <mass
        value="0.911976961838319" />
      <inertia
        ixx="0.001557872500184"
        ixy="-1.82431705562564E-09"
        ixz="2.07922879385151E-08"
        iyy="0.0012763862501827"
        iyz="-1.43394136920931E-08"
        izz="0.00165040465761083" />
    </inertial>
    <visual>
      <origin
        xyz="0 0 0"
        rpy="0 0 0" />
      <geometry>
        <mesh
          filename="package://carver_description/meshes/LD_SICK_Link.STL" />
      </geometry>
      <material
        name="">
        <color
          rgba="0.792156862745098 0.819607843137255 0.933333333333333 1" />
      </material>
    </visual>
    <collision>
      <origin
        xyz="0 0 0"
        rpy="0 0 0" />
      <geometry>
        <mesh
          filename="package://carver_description/meshes/LD_SICK_Link.STL" />
      </geometry>
    </collision>
  </link>
  <joint
    name="base_LD_SICK_joint"
    type="fixed">
    <origin
      xyz="0.94232 0 0.215"
      rpy="0 0 0" />
    <parent
      link="base_link" />
    <child
      link="LD_SICK_Link" />
    <axis
      xyz="0 0 0" />
  </joint>
  <link
    name="RPLIDAR_LB_Link">
    <inertial>
      <origin
        xyz="-0.000213861534884563 -9.3054388941527E-05 -0.0160849090284956"
        rpy="0 0 0" />
      <mass
        value="0.0328083847884949" />
      <inertia
        ixx="1.08465576772133E-05"
        ixy="-2.43583766252435E-09"
        ixz="1.62330710188916E-08"
        iyy="1.0788186102816E-05"
        iyz="-4.20828622547995E-09"
        izz="1.9637602202392E-05" />
    </inertial>
    <visual>
      <origin
        xyz="0 0 0"
        rpy="0 0 0" />
      <geometry>
        <mesh
          filename="package://carver_description/meshes/RPLIDAR_LB_Link.STL" />
      </geometry>
      <material
        name="">
        <color
          rgba="0.4 0.4 0.4 1" />
      </material>
    </visual>
    <collision>
      <origin
        xyz="0 0 0"
        rpy="0 0 0" />
      <geometry>
        <mesh
          filename="package://carver_description/meshes/RPLIDAR_LB_Link.STL" />
      </geometry>
    </collision>
  </link>
  <joint
    name="base_RPLIDAR_LB_joint"
    type="fixed">
    <origin
      xyz="-0.85116 0.34072 0.085015"
      rpy="0 0 3.1412" />
    <parent
      link="base_link" />
    <child
      link="RPLIDAR_LB_Link" />
    <axis
      xyz="0 0 0" />
  </joint>
  <link
    name="IMU_R_Link">
    <inertial>
      <origin
        xyz="0.000436358638984457 8.6673619422422E-05 -0.00106324875441716"
        rpy="0 0 0" />
      <mass
        value="0.000983130183652043" />
      <inertia
        ixx="2.7278081479223E-08"
        ixy="-1.86463715352976E-11"
        ixz="-1.83135757569426E-11"
        iyy="4.80453464098755E-08"
        iyz="1.8157517189248E-12"
        izz="7.48563776021962E-08" />
    </inertial>
    <visual>
      <origin
        xyz="0 0 0"
        rpy="0 0 0" />
      <geometry>
        <mesh
          filename="package://carver_description/meshes/IMU_R_Link.STL" />
      </geometry>
      <material
        name="">
        <color
          rgba="0.792156862745098 0.819607843137255 0.933333333333333 1" />
      </material>
    </visual>
    <collision>
      <origin
        xyz="0 0 0"
        rpy="0 0 0" />
      <geometry>
        <mesh
          filename="package://carver_description/meshes/IMU_R_Link.STL" />
      </geometry>
    </collision>
  </link>
  <joint
    name="base_IMU_R_joint"
    type="fixed">
    <origin
      xyz="0.027169 -0.019101 0.383"
      rpy="0 0 0" />
    <parent
      link="base_link" />
    <child
      link="IMU_R_Link" />
    <axis
      xyz="0 0 0" />
  </joint>
  <link
    name="IMU_L_Link">
    <inertial>
      <origin
        xyz="0.000436358638983749 8.66736194121698E-05 -0.00106324875441677"
        rpy="0 0 0" />
      <mass
        value="0.000983130183652038" />
      <inertia
        ixx="2.7278081479223E-08"
        ixy="-1.86463715354835E-11"
        ixz="-1.83135757570051E-11"
        iyy="4.80453464098758E-08"
        iyz="1.81575171892318E-12"
        izz="7.48563776021965E-08" />
    </inertial>
    <visual>
      <origin
        xyz="0 0 0"
        rpy="0 0 0" />
      <geometry>
        <mesh
          filename="package://carver_description/meshes/IMU_L_Link.STL" />
      </geometry>
      <material
        name="">
        <color
          rgba="0.792156862745098 0.819607843137255 0.933333333333333 1" />
      </material>
    </visual>
    <collision>
      <origin
        xyz="0 0 0"
        rpy="0 0 0" />
      <geometry>
        <mesh
          filename="package://carver_description/meshes/IMU_L_Link.STL" />
      </geometry>
    </collision>
  </link>
  <joint
    name="base_IMU_L_joint"
    type="fixed">
    <origin
      xyz="0.029419 0.019139 0.383"
      rpy="0 0 0" />
    <parent
      link="base_link" />
    <child
      link="IMU_L_Link" />
    <axis
      xyz="0 0 0" />
  </joint>
  <link
    name="RPLIDAR_RF_Link">
    <inertial>
      <origin
        xyz="0 0 0"
        rpy="0 0 0" />
      <mass
        value="0" />
      <inertia
        ixx="0"
        ixy="0"
        ixz="0"
        iyy="0"
        iyz="0"
        izz="0" />
    </inertial>
    <visual>
      <origin
        xyz="0 0 0"
        rpy="0 0 0" />
      <geometry>
        <mesh
          filename="package://carver_description/meshes/RPLIDAR_RF_Link.STL" />
      </geometry>
      <material
        name="">
        <color
          rgba="1 1 1 1" />
      </material>
    </visual>
    <collision>
      <origin
        xyz="0 0 0"
        rpy="0 0 0" />
      <geometry>
        <mesh
          filename="package://carver_description/meshes/RPLIDAR_RF_Link.STL" />
      </geometry>
    </collision>
  </link>
  <joint
    name="base_RPLIDAR_RF_joint"
    type="fixed">
    <origin
      xyz="0.91252 -0.38133 0.15392"
      rpy="0 0 0" />
    <parent
      link="base_link" />
    <child
      link="RPLIDAR_RF_Link" />
    <axis
      xyz="0 0 0" />
  </joint>
</robot>